<?xml version='1.0'?>
<sdf version='1.4'>
    <model name="my_robot">
        <static>false</static>
        <self_collide>1</self_collide>
        <link name='chassis'>
            <pose>0 0 .05 0 0 0</pose>
            <inertial>
            <mass>100.0 </mass>
            </inertial>
            <collision name='collision'>
                <geometry>
                    <cylinder>
                        <radius>.5</radius>
                        <length>.1</length>
                    </cylinder>
                </geometry>
            </collision>

            <visual name='visual'>
                <geometry>
                    <cylinder>
                        <radius>.5</radius>
                        <length>.1</length>
                    </cylinder>
                </geometry>
                <material>
                    <script>
                        <name>
                            Gazebo/Black
                        </name>
                        <uri>file://media/materials/scripts/gazebo.material</uri>
                    </script>
                </material>
            </visual>
        </link>
        <link name='arm1'>
            <pose>0 0 .125 0 0 0</pose>
            <gravity> 0 </gravity>

            <inertial>
            <mass>50 </mass>
            </inertial>
            <collision name='collision'>
                <geometry>
                    <cylinder>
                        <radius>.1</radius>
                        <length>.05</length>
                    </cylinder>
                </geometry>
            </collision>

            <visual name='visual'>
                <geometry>
                    <cylinder>
                        <radius>.1</radius>
                        <length>.05</length>
                    </cylinder>
                </geometry>
                <material>
                    <script>
                        <name>
                            Gazebo/Yellow
                        </name>
                        <uri>file://media/materials/scripts/gazebo.material</uri>
                    </script>
                </material>
            </visual>
        </link>
        <link name='arm2'>
            <pose>0 0 1.15 0 0 0</pose>
           <gravity> 0 </gravity>
            <inertial>
            <mass>20 </mass>

            </inertial>

            <collision name='collision'>
                <geometry>
                    <cylinder>
                        <radius>.05</radius>
                        <length>2.0</length>
                    </cylinder>
                </geometry>
            </collision>

            <visual name='visual'>
                <geometry>
                    <cylinder>
                        <radius>.05</radius>
                        <length>2.0</length>
                    </cylinder>
                </geometry>
                <material>
                    <script>
                        <name>
                            Gazebo/white
                        </name>
                        <uri>file://media/materials/scripts/gazebo.material</uri>
                    </script>
                </material>
            </visual>
        </link>

        <link name='arm3'>
            <pose>0 0 2.65 0 0 0</pose>
            <inertial>
            <mass>1 </mass>
            </inertial>
            <collision name='collision'>
                <geometry>
                    <cylinder>
                        <radius>.05</radius>
                        <length>1.0</length>
                    </cylinder>
                </geometry>
            </collision>

            <visual name='visual'>
                <geometry>
                    <cylinder>
                        <radius>.05</radius>
                        <length>1</length>
                    </cylinder>
                </geometry>
                <material>
                    <script>
                        <name>
                            Gazebo/Black
                        </name>
                        <uri>file://media/materials/scripts/gazebo.material</uri>
                    </script>
                </material>
            </visual>
        </link>
        <link name='arm4'>
            <pose>0 0 3.4 0 0 0</pose>
            <gravity>0</gravity>
             <inertial>
            <mass>0.5 </mass>

            </inertial>

            <collision name='collision'>
                <geometry>
                    <cylinder>
                        <radius>.05</radius>
                        <length>.5</length>
                    </cylinder>
                </geometry>
            </collision>

            <visual name='visual'>
                <geometry>
                    <cylinder>
                        <radius>.05</radius>
                        <length>.5</length>
                    </cylinder>
                </geometry>
                <material>
                    <script>
                        <name>
                            Gazebo/white
                        </name>
                        <uri>file://media/materials/scripts/gazebo.material</uri>
                    </script>
                </material>
            </visual>
        </link>


        
        <link name="hand">
            <gravity>0</gravity>
            <pose>0.0 0.0 3.7 0 0 0</pose>
            <inertial>
                <inertia>
                    <ixx>0.01</ixx>
                    <ixy>0</ixy>
                    <ixz>0</ixz>
                    <iyy>0.01</iyy>
                    <iyz>0</iyz>
                    <izz>0.01</izz>
                </inertia>
                <mass>0.5</mass>
            </inertial>
            <collision name="collision">
                <geometry>
                    <box>
                        <size>0.1 0.2 0.1</size>
                    </box>
                </geometry>
            </collision>
            <visual name="visual">
                <geometry>
                    <box>
                        <size>0.1 0.2 0.1</size>
                    </box>
                </geometry>
                <material>
                    <script>
                        <name>Gazebo/Black</name>
                        <uri>file://media/materials/scripts/gazebo.material</uri>
                    </script>

                </material>
            </visual>
        </link>


  
        <link name="hand_joint">
            <gravity>0</gravity>
            <pose>0.0 0.0 3.8 0 0 0</pose>
            <collision name="collision">
                <geometry>
                    <box>
                        <size>0.1 0.2 0.1</size>
                    </box>
                </geometry>
            </collision>
            <visual name="visual">
                <geometry>
                    <box>
                        <size>0.1 0.2 0.1</size>
                    </box>
                </geometry>
                <material>
                    <script>
                        <name>
                            Gazebo/White
                        </name>
                        <uri>file://media/materials/scripts/gazebo.material</uri>
                    </script>
                </material>
            </visual>
        </link>
        <link name="left_hand">
            <self_collide>1</self_collide>
            <pose>0.1 0.2 3.8 0 0 -0.78539</pose>
            <inertial>
                <inertia>
                    <ixx>0.01</ixx>
                    <ixy>0</ixy>
                    <ixz>0</ixz>
                    <iyy>0.01</iyy>
                    <iyz>0</iyz>
                    <izz>0.01</izz>
                </inertia>
                <mass>0.1</mass>
            </inertial>
            <collision name="collision">
                <geometry>
                    <box>
                        <size>0.1 0.3 0.1</size>
                    </box>
                </geometry>
            </collision>
            <visual name="visual">
                <geometry>
                    <box>
                        <size>0.1 0.3 0.1</size>
                    </box>
                </geometry>
                <material>
                    <script>
                        <name>
                            Gazebo/Black
                        </name>
                        <uri>file://media/materials/scripts/gazebo.material</uri>
                    </script>
                </material>
            </visual>
        </link>
        <link name="left_hand_end">
            <self_collide>1</self_collide>
            <pose>0.336 0.3 3.8 0 0 1.5707</pose>
            <inertial>
                <inertia>
                    <ixx>0.01</ixx>
                    <ixy>0</ixy>
                    <ixz>0</ixz>
                    <iyy>0.01</iyy>
                    <iyz>0</iyz>
                    <izz>0.01</izz>
                </inertia>
                <mass>0.1</mass>
            </inertial>
            <collision name="collision">
                <geometry>
                    <box>
                        <size>0.1 0.2 0.1</size>
                    </box>
                </geometry>
            </collision>
            <visual name="visual">
                <geometry>
                    <box>
                        <size>0.1 0.2 0.1</size>
                    </box>
                </geometry>
                <material>
                    <script>
                        <name>
                            Gazebo/White
                        </name>
                        <uri>file://media/materials/scripts/gazebo.material</uri>
                    </script>
                </material>
            </visual>
        </link>
        <link name="right_hand">
            <self_collide>1</self_collide>
            <pose>0.1 -0.2 3.8 0 0 .78539</pose>
            <inertial>
                <inertia>
                    <ixx>0.01</ixx>
                    <ixy>0</ixy>
                    <ixz>0</ixz>
                    <iyy>0.01</iyy>
                    <iyz>0</iyz>
                    <izz>0.01</izz>
                </inertia>
                <mass>0.1</mass>
            </inertial>
            <collision name="collision">
                <geometry>
                    <box>
                        <size>0.1 0.3 0.1</size>
                    </box>
                </geometry>
            </collision>
            <visual name="visual">
                <geometry>
                    <box>
                        <size>0.1 0.3 0.1</size>
                    </box>
                </geometry>
                <material>
                    <script>
                        <name>
                            Gazebo/Black
                        </name>
                        <uri>file://media/materials/scripts/gazebo.material</uri>
                    </script>
                </material>
            </visual>
        </link>
        <link name="right_hand_end">
            <self_collide>1</self_collide>
            <pose>0.336 -0.3 3.8 0 0 1.5707</pose>
            <inertial>
                <inertia>
                    <ixx>0.01</ixx>
                    <ixy>0</ixy>
                    <ixz>0</ixz>
                    <iyy>0.01</iyy>
                    <iyz>0</iyz>
                    <izz>0.01</izz>
                </inertia>
                <mass>0.1</mass>
            </inertial>
            <collision name="collision">
                <geometry>
                    <box>
                        <size>0.1 0.2 0.1</size>
                    </box>
                </geometry>
            </collision>
            <visual name="visual">
                <geometry>
                    <box>
                        <size>0.1 0.2 0.1</size>
                    </box>
                </geometry>
                <material>
                    <script>
                        <name>
                            Gazebo/White
                        </name>
                        <uri>file://media/materials/scripts/gazebo.material</uri>
                    </script>
                </material>
            </visual>
        </link>
        <link name='box'>
            <self_collide>1</self_collide>
            <inertial>
                <mass>50.0</mass>
            </inertial>
            <pose>1.8 2 0.15 0 -0 0</pose>
            <collision name='collision'>
                <geometry>
                    <box>
                        <size>0.3 0.3 0.3</size>
                    </box>
                </geometry>
            </collision>
            <visual name='visual'>
                <geometry>
                    <box>
                        <size>0.3 0.3 0.3</size>
                    </box>
                </geometry>
                <material>
                    <script>
                        <name>Gazebo/Blue</name>
                        <uri>file://media/materials/scripts/gazebo.material</uri>
                    </script>
                </material>
            </visual>

        </link>



        <joint type="revolute" name="chasis_arm1_joint">
            <pose>0 0 -0.025 0 0 0</pose>
            <child>arm1</child>
            <parent>chassis</parent>
            <axis>
                <xyz>0 0 1</xyz>
                <dynamics>
               <damping> 1.0</damping>
               <friction>.3 </friction>
                </dynamics>

               <limit>
                <lower>-1.0 </lower>
                <upper>1.0 </upper>
                <effort> 40 </effort>
                <velocity>1.0 </velocity>
                </limit>     
            </axis>
        </joint>

         <joint type="revolute" name="arm1_arm2_joint">
            <pose>0 0 -1 0 0 0</pose>
            <child>arm2</child>
            <parent>arm1</parent>
            <axis>
                <xyz>1 0 0</xyz>
            </axis>
        </joint>

   <joint type="revolute" name="arm2_arm3_joint">
            <pose>0 0 -0.5 0 0 0</pose>
            <child>arm3</child>
            <parent>arm2</parent>
            <axis>
                <xyz>1 0 0</xyz>
                <dynamics>
               <damping> 1.0</damping>
               <friction>.3 </friction>
                </dynamics>
               <limit>
                <lower>-1.0 </lower>
                <upper>1.0 </upper>
                <effort> 40 </effort>
                <velocity>1.0 </velocity>
                </limit>     
            </axis>
        </joint>

         <joint type="revolute" name="arm3_arm4_joint">
            <pose>0 0 -0.25 0 0 0</pose>
            <child>arm4</child>
            <parent>arm3</parent>
            <axis>
                <xyz>1 0 0</xyz>
                <dynamics>
               <damping> 1.0</damping>
               <friction>.3 </friction>
                </dynamics>

               <limit>
                <lower>-1.0 </lower>
                <upper>1.0 </upper>
                <effort> 40 </effort>
                <velocity>1.0 </velocity>
                </limit>     
            </axis>
        </joint>

    
        <joint name="arm4_hand_joint" type="revolute">
            <parent>
                arm4
            </parent>
            <child>
                hand
            </child>
            <pose>
                0 0 -0.05 0 0 0</pose>
            <axis>
                <xyz>
                    1 0 0
                </xyz>
                <dynamics>
                    <damping>
                        1.0</damping>
                    <friction>
                        0.3
                    </friction>

                </dynamics>

            </axis>
        </joint>
        <joint name="hand_joint" type="revolute">
            <parent>
                hand
            </parent>
            <child>
                hand_joint
            </child>
            <pose>
                0 0 -0.05 0 0 0</pose>
            <axis>
                <xyz>
                    0 0 1
                </xyz>
                <dynamics>
                    <damping>
                        1.0</damping>
                    <friction>
                        0.3
                    </friction>

                </dynamics>

            </axis>
        </joint>
        <joint name="hand_left_hand" type="revolute">
            <pose>0 -0.15 0 0 0 0</pose>
            <child>left_hand</child>
            <parent>hand_joint</parent>
            <axis>
                <limit>
                    <lower>-0.4</lower>
                    <upper>0.4</upper>
                </limit>
                <xyz>0 0 1</xyz>
            </axis>
        </joint>
        <joint name="left_hand_end_joint" type="revolute">
            <pose>0 0.1 0 0 0 0</pose>
            <child>left_hand_end</child>
            <parent>left_hand</parent>
            <axis>
                <limit>
                    <lower>-0.4</lower>
                    <upper>0.4</upper>
                </limit>
                <xyz>0 0 1</xyz>
            </axis>
        </joint>
        <joint name="hand_right_hand" type="revolute">
            <pose>0 0.15 0 0 0 0</pose>
            <child>right_hand</child>
            <parent>hand_joint</parent>
            <axis>
                <limit>
                    <lower>-0.4</lower>
                    <upper>0.4</upper>
                </limit>
                <xyz>0 0 1</xyz>
            </axis>
        </joint>
        <joint name="right_hand_end_joint" type="revolute">
            <pose>0 0.1 0 0 0 0</pose>
            <child>right_hand_end</child>
            <parent>right_hand</parent>
            <axis>
                <limit>
                    <lower>-0.4</lower>
                    <upper>0.4</upper>
                </limit>
                <xyz>0 0 1</xyz>
            </axis>
        </joint>




        <plugin name="arm_control" filename="libarm_gazebo.so" />

    </model>
</sdf>
